Workbook
Name 印刷: 見積表紙!#REF!
Name 印刷: #REF!
Name 印刷: #REF!
Name 印刷: 直接人件費!#REF!
Name 印刷: 内訳書!#REF!
Name 印刷: #REF!

Sheet 見積表紙
C1: 奈）中和土木事務所 | D1: 45846
E3: =IF(A34=1,"平成 年 月 日",IF(A34=2,"平成 "&YEAR(D1+A33)-1988&"年 月 日",IF(A34=3,"平成 "&YEAR(D1+A33)-1988&"年 "&MONTH(D1+A33)&"月 日",$D$1+A33))) -> 45846
A4: =IF(LEFT($C1,1)="大","大阪府",IF(LEFT($C1,1)="京","京都府",IF(LEFT($C1,1)="兵","兵庫県",IF(LEFT($C1,1)="福","福井県",IF(LEFT($C1,1)="滋","滋賀県",IF(LEFT($C1,1)="奈","奈良県",IF(LEFT($C1,1)="和","和歌山県",IF(LEFT($C$1,1)="国","国土交通省 近畿地方整備局","直接入力")))))))) -> 奈良県
A5: =IF(A27<>1," "&MID(C1,3,50)&B28&B29&B30&B31&B34&" "&$A29&" "&B36,IF(LEFT($C$1,1)="和"," 和歌山県知事 "&$A29&" 殿",IF(LEFT($C$1,1)="滋"," 滋賀県知事 "&$A29&" 殿",IF(LEFT($C$1,1)="兵"," 兵庫県知事 "&$A29&" 殿",IF(LEFT($C$1,1)="奈"," 奈良県知事 "&$A29&" 殿",IF(LEFT($C$1,1)="福"," 福井県知事 "&$A$29&" 殿",IF(LEFT($C$1,1)="京"," 京都府知事 "&$A$29&" 殿"))))))) -> 中和土木事務所長 殿
D7: =IF(LEFT($C1,1)="滋","大津市京町4丁目5番13号",IF(LEFT($C1,1)="兵","神戸市中央区御幸通6丁目1番15号",IF(LEFT($C1,1)="福","福井市生部町5丁目17番2号",IF(LEFT($C1,1)="奈","奈良市内侍原町6番地",IF(LEFT($C1,1)="和","和歌山県和歌山市太田1-6-13","大阪市中央区城見1丁目4番70号"))))) -> 奈良市内侍原町6番地
D8: 八千代エンジニヤリング株式会社
D9: =IF(LEFT($C1,1)="滋","滋賀事務所",IF(LEFT($C1,1)="兵","兵庫事務所",IF(LEFT($C1,1)="福","福井事務所",IF(LEFT($C1,1)="奈","奈良事務所",IF(LEFT($C1,1)="和","和歌山事務所","大阪支店"))))) -> 奈良事務所
D10: =IF(LEFT($C1,1)="兵","所 長",IF(LEFT($C1,1)="福","所 長",IF(LEFT($C1,1)="奈","所 長",IF(LEFT($C1,1)="滋","所 長",IF(LEFT($C1,1)="和","所 長","取締役 執行役員 支店長"))))) -> 所 長 | E10: =IF(LEFT($C1,1)="滋","安藤 光明",IF(LEFT($C1,1)="兵","濱千代 拓馬",IF(LEFT($C1,1)="福","安藤 光明",IF(LEFT($C1,1)="奈","田村 淳",IF(LEFT($C1,1)="和","林 宏幸","渡邉 智明"))))) -> 田村 淳
C12: 御見積書
C15: =IF($C$16=0,"歩掛り見積","")
C16: =内訳書!C3 -> 7530000
C17: =INT(C16*見積表紙!F29) -> 753000
C18: =SUM(C16:C17) -> 8283000
A21: 件名、田原本停車場線 歩道設置検討業務委託（防災・安全（道環））
A23: 見積条件：
C25: 上記のとおり御見積申し上げます。 | D25: 見積有効期限 | E25: =VLOOKUP($C28,$C29:$D39,2,FALSE)+E28 -> 46112
A26: 1 | B26: 100 | C26: 7 | D26: 歩掛有効期限 | E26: =VLOOKUP($C26,$C29:$D39,2,FALSE) -> 46112
B27: 宛先追加以下記入 | C27: 7 | D27: 単価有効期限 | E27: =VLOOKUP($C27,$C29:$D39,2,FALSE) -> 46112
A28: 知事宛：Ａ27に1 | C28: 7 | D28: 有効期限の強制表示 | F28: 消費税率
C29: 1 | D29: 43921 | E29: 平成31年度 | F29: 0.1
A30: 宛先名前：Ａ29に記入 | C30: 2 | D30: 44286 | E30: 令和2年度
C31: 3 | D31: 44651 | E31: 令和3年度
A32: 府県名の消去：A31に記入 | C32: 4 | D32: 45016 | E32: 令和4年度
A33: 0 | C33: 5 | D33: 45382 | E33: 令和5年度
B34: 長 | C34: 6 | D34: 45747 | E34: 令和6年度
A35: 日付：全抜き ：A34に1 | B35: 役称変更：上記変 | C35: 7 | D35: 46112 | E35: 令和7年度
A36: 日付：月日抜き：A34に2 | B36: 殿 | C36: 8 | D36: 46477 | E36: 令和8年度
A37: 日付：日抜き ：A34に3 | B37: 敬称変更：上記変 | C37: 9 | D37: 46843 | E37: 令和9年度
C38: 10 | D38: 47208 | E38: 令和10年度
C39: 11 | D39: 47573 | E39: 令和11年度
A40: 【その他経費率】 | B40: 【一般経費率】
A41: 0.35 | B41: 0.35 | C41: 条件等設定部分：絶対に消さないでください！
A43: 【積算区分】
A44: 設計
A45: 測量
A46: 調査
A47: 【旧積算の技術難易度】
A48: 易
A49: 中
A50: 難

Sheet 内訳書
B1: 新 | C1: 技術経費率：技術難易： | D1: 中 | F1: 単価： | G1: =VLOOKUP(見積表紙!$C$28,見積表紙!$C$29:$E$39,3,FALSE) -> 令和7年度 | H1: 10000
B2: =直接人件費!B2 -> 田原本停車場線 歩道設置検討業務委託（防災・安全（道環））
B3: 金 | C3: =G25 -> 7530000 | D3: 円也
B4: 名 称 | C4: 仕 様 | D4: 単位 | E4: 数 量 | F4: 単 価 | G4: 金 額 | H4: 摘 要
B5: =IF(B1="新","①直接人件費",IF(直接人件費!O3="測量","１．直 接 測 量 費",IF(直接人件費!O3="調査","１．直 接 調 査 費","１．直 接 人 件 費"))) -> ①直接人件費 | D5: 式 | E5: 1 | G5: =直接人件費!O29 -> 3005350 | H5: 直接人件費明細書参照
B14: =IF(B1="新","②直接経費（積上げ部分）",IF(直接人件費!O3="測量","２．間 接 測 量 費",IF(直接人件費!O3="調査","２．間 接 調 査 費","２．直 接 経 費"))) -> ②直接経費（積上げ部分） | D14: 式 | E14: 1 | G14: =SUM(G15:G19) -> 271933
B15: 旅費交通費 | D15: 式 | E15: 1 | G15: =G33 -> 18933
B16: 電子成果品作成費 | D16: 式 | E16: 1 | G16: =G29 -> 253000
B20: =IF(B1="新","③その他原価",IF(H22=0,"","３．諸 経 費")) -> ③その他原価 | D20: =IF(H22=0,"","式") -> 式 | E20: =IF(H22=0,"",1) -> 1 | G20: =INT(IF(B1="新",G5*INT(見積表紙!A41/(1-見積表紙!A41)*H29+0.5)/H29,(G5*H20))) -> 1618380 | H20: =IF(B1="新","①×α/(1-α)：α="&見積表紙!A41*100&"%",IF(H22=0,0,120%)) -> ①×α/(1-α)：α=35%
B21: =IF(直接人件費!O3="測量"," 諸 経 費",IF(直接人件費!O3="調査"," 諸 経 費","")) | D21: =IF(H22=0,"式","") | E21: =IF(H22=0,1,0) -> 0 | G21: =INT((G5+G14)*H21) -> 0 | H21: =IF(直接人件費!O3="設計",0,IF(直接人件費!O3="測量",IF((G5+G14)<=500000,0.958,IF((G5+G14)<=100000000,ROUND(288.5*(G5+G14)^(-0.084)/100,3),0.614)),IF((G5+G14)<=1000000,0.599,IF((G5+G14)<=30000000,ROUND(285.3*(G5+G14)^(-0.113)/100,3),0.408)))) -> 0
B22: =IF(B1="新","④一般管理費等",IF(H22=0,"","４．技 術 経 費")) -> ④一般管理費等 | C22: =D1 -> 中 | D22: =IF(H22=0,"","式") -> 式 | E22: =IF(H22=0,"",1) -> 1 | G22: =INT(IF(B1="新",(G5+G14+G20)*INT(見積表紙!B41/(1-見積表紙!B41)*H29+0.5)/H29,((G5+G20)*H22))) -> 2636314 | H22: =IF(B1="新","(①+②+③)×β/(1-β)：β="&見積表紙!B41*100&"%",IF(AND(直接人件費!O3="設計",C22="易"),0.2,IF(AND(直接人件費!O3="設計",C22="中"),0.3,IF(AND(直接人件費!O3="設計",C22="難"),0.4,0)))) -> (①+②+③)×β/(1-β)：β=35%
B24: 合 計 | G24: =G5+G14+SUM(G20:G23) -> 7531977
G25: =INT(G24/H1)*H1 -> 7530000 | H25: 改め
H26: 八千代エンジニヤリング株式会社
D27: 回数 | E27: 1回当り人数 | F27: 片道料金(税込) | G27: 旅費交通費(打合せ)
C28: 旅費：打合せ回数・人数 | D28: 3 | E28: 2 | G28: =INT(2*D28*E28*INT(F28/(1+見積表紙!F29))) -> 0 | H28: 経費等率の端数処理(変更禁止!)
C29: 電子成果品作成費 | D29: 概略・予備・詳細 | G29: =IF(INT((INT(G5/1000))^0.45*6.9)*1000>700000,700000,IF(INT((INT(G5/1000))^0.45*6.9)*1000<20000,20000,INT((INT(G5/1000))^0.45*6.9)*1000)) -> 253000 | H29: 10000
C30: （国交省基準） | D30: その他 | G30: =IF(INT((INT(G5/1000))^0.38*5.1)*1000>250000,250000,IF(INT((INT(G5/1000))^0.38*5.1)*1000<20000,20000,INT((INT(G5/1000))^0.38*5.1)*1000)) -> 106000 | H30: ※金額の端数処理は、L1セルで設定
D31: 測量業務 | G31: =INT(G5*0.0056) -> 16829
D32: 地質調査業務 | G32: =INT(G5*0.0214) -> 64314
D33: 土木設計業務 | G33: =INT(G5*0.0063) -> 18933
D34: 調査、計画業務 | G34: =INT(G5*0.0149) -> 44779

Sheet 直接人件費
E1: 2 | F1: 3 | G1: 4 | H1: 5 | I1: 6 | J1: 7 | K1: 8 | L1: 9 | M1: 10
B2: =MID(見積表紙!A$21,4,100) -> 田原本停車場線 歩道設置検討業務委託（防災・安全（道環））
H3: 直 接 人 件 費 明 細 書 | O3: 設計
B4: 区分 | E4: =HLOOKUP($B4,単価!$A$1:$IN$112,IF($O3="設計",$E1,IF($O3="測量",$E1+9,IF($O3="調査",$E1+20,"???")))) -> 主任技術者 | F4: =HLOOKUP($B4,単価!$A$1:$IN$112,IF($O3="設計",$F1,IF($O3="測量",$F1+9,IF($O3="調査",$F1+20,"???")))) -> 理事、技師長 | G4: =HLOOKUP($B4,単価!$A$1:$IN$112,IF($O3="設計",$G1,IF($O3="測量",$G1+9,IF($O3="調査",$G1+20,"???")))) -> 主任技師 | H4: =HLOOKUP($B4,単価!$A$1:$IN$112,IF($O3="設計",$H1,IF($O3="測量",$H1+9,IF($O3="調査",$H1+20,"???")))) -> 技師(Ａ) | I4: =HLOOKUP($B4,単価!$A$1:$IN$112,IF($O3="設計",$I1,IF($O3="測量",$I1+9,IF($O3="調査",$I1+20,"???")))) -> 技師(Ｂ) | J4: =HLOOKUP($B4,単価!$A$1:$IN$112,IF($O3="設計",$J1,IF($O3="測量",$J1+9,IF($O3="調査",$J1+20,"???")))) -> 技師(Ｃ) | K4: =HLOOKUP($B4,単価!$A$1:$IN$112,IF($O3="設計",$K1,IF($O3="測量",$K1+9,IF($O3="調査",$K1+20,"???")))) -> 技術員 | L4: =HLOOKUP($B4,単価!$A$1:$IN$112,IF($O3="設計",$L1,IF($O3="測量",$L1+9,IF($O3="調査",$L1+18,"???")))) -> 製図工 | N4: 直接人件費 | P4: 労務費
B5: 項 目 | C5: 単位 | D5: 数量 | E5: =HLOOKUP(内訳書!$G$1,単価!$A$1:$IN$112,IF($O3="設計",$E1,IF($O3="測量",$E1+9,IF($O3="調査",$E1+20,"???")))) -> 88600 | F5: =HLOOKUP(内訳書!$G$1,単価!$A$1:$IN$112,IF($O3="設計",$F1,IF($O3="測量",$F1+9,IF($O3="調査",$F1+20,"???")))) -> 77500 | G5: =HLOOKUP(内訳書!$G$1,単価!$A$1:$IN$112,IF($O3="設計",$G1,IF($O3="測量",$G1+9,IF($O3="調査",$G1+20,"???")))) -> 66900 | H5: =HLOOKUP(内訳書!$G$1,単価!$A$1:$IN$112,IF($O3="設計",$H1,IF($O3="測量",$H1+9,IF($O3="調査",$H1+20,"???")))) -> 59600 | I5: =HLOOKUP(内訳書!$G$1,単価!$A$1:$IN$112,IF($O3="設計",$I1,IF($O3="測量",$I1+9,IF($O3="調査",$I1+20,"???")))) -> 48500 | J5: =HLOOKUP(内訳書!$G$1,単価!$A$1:$IN$112,IF($O3="設計",$J1,IF($O3="測量",$J1+9,IF($O3="調査",$J1+20,"???")))) -> 40300 | K5: =HLOOKUP(内訳書!$G$1,単価!$A$1:$IN$112,IF($O3="設計",$K1,IF($O3="測量",$K1+9,IF($O3="調査",$K1+20,"???")))) -> 36100 | L5: =HLOOKUP(内訳書!$G$1,単価!$A$1:$IN$112,IF($O3="設計",$L1,IF($O3="測量",$L1+9,IF($O3="調査",$L1+18,"???")))) -> 0 | N5: 人工計 | O5: 金 額 | P5: 人工計 | Q5: 金 額 | R5: 摘 要
B6: （１）業務計画 | C6: 式 | D6: 1 | G6: 0.5 | H6: 1.5 | I6: 1 | N6: =SUM(E6:K6) -> 3 | O6: =INT(SUMPRODUCT($E$5:$K$5,$E6:$K6)) -> 171350 | P6: =SUM(L6:M6) -> 0 | Q6: =INT(SUMPRODUCT($L5:$M5,$L6:$M6)) -> 0
B7: （２）現況調査 | C7: 式 | D7: 1 | H7: 1 | I7: 1.5 | J7: 1.5 | N7: =SUM(E7:K7) -> 4 | O7: =INT(SUMPRODUCT($E$5:$K$5,$E7:$K7)) -> 192800 | P7: =SUM(L7:M7) -> 0 | Q7: =INT(SUMPRODUCT($L5:$M5,$L7:$M7)) -> 0
B8: （３）交通量調査 | C8: 式 | D8: 1 | N8: =SUM(E8:K8) -> 0 | O8: =INT(SUMPRODUCT($E$5:$K$5,$E8:$K8)) -> 0 | P8: =SUM(L8:M8) -> 0 | Q8: =INT(SUMPRODUCT($L5:$M5,$L8:$M8)) -> 0
B9: １）調査実施（①～④：自動車、自転車、歩行者） | C9: 式 | D9: 1 | J9: 1.5 | K9: 12 | N9: =SUM(E9:K9) -> 13.5 | O9: =INT(SUMPRODUCT($E$5:$K$5,$E9:$K9)) -> 493650 | P9: =SUM(L9:M9) -> 0 | Q9: =INT(SUMPRODUCT($L5:$M5,$L9:$M9)) -> 0 | R9: 4箇所
B10: １）調査実施（⑤～⑥：歩行者） | C10: 式 | D10: 1 | J10: 0.5 | K10: 4 | N10: =SUM(E10:K10) -> 4.5 | O10: =INT(SUMPRODUCT($E$5:$K$5,$E10:$K10)) -> 164550 | P10: =SUM(L10:M10) -> 0 | Q10: =INT(SUMPRODUCT($L5:$M5,$L10:$M10)) -> 0 | R10: 2箇所
B11: ２）調査結果とりまとめ（①～④：自動車、自転車、歩行者） | C11: 式 | D11: 1 | K11: 2 | N11: =SUM(E11:K11) -> 2 | O11: =INT(SUMPRODUCT($E$5:$K$5,$E11:$K11)) -> 72200 | P11: =SUM(L11:M11) -> 0 | Q11: =INT(SUMPRODUCT($L5:$M5,$L11:$M11)) -> 0 | R11: 4箇所
B12: ２）調査結果とりまとめ（⑤～⑥：歩行者） | C12: 式 | D12: 1 | K12: 1 | N12: =SUM(E12:K12) -> 1 | O12: =INT(SUMPRODUCT($E$5:$K$5,$E12:$K12)) -> 36100 | P12: =SUM(L12:M12) -> 0 | Q12: =INT(SUMPRODUCT($L5:$M5,$L12:$M12)) -> 0 | R12: 2箇所
B13: （４）道路利用に関する実態調査・とりまとめ | C13: 式 | D13: 1 | H13: 2 | I13: 3 | J13: 3 | K13: 9 | N13: =SUM(E13:K13) -> 17 | O13: =INT(SUMPRODUCT($E$5:$K$5,$E13:$K13)) -> 710500 | P13: =SUM(L13:M13) -> 0 | Q13: =INT(SUMPRODUCT($L5:$M5,$L13:$M13)) -> 0
B14: （５）歩道設置の必要性の検討 | C14: 式 | D14: 1 | G14: 1.5 | H14: 4 | I14: 4 | J14: 1 | N14: =SUM(E14:K14) -> 10.5 | O14: =INT(SUMPRODUCT($E$5:$K$5,$E14:$K14)) -> 573050 | P14: =SUM(L14:M14) -> 0 | Q14: =INT(SUMPRODUCT($L5:$M5,$L14:$M14)) -> 0
B15: （６）関係機関協議資料作成 | C15: 式 | D15: 1 | H15: 1 | I15: 2 | J15: 1 | N15: =SUM(E15:K15) -> 4 | O15: =INT(SUMPRODUCT($E$5:$K$5,$E15:$K15)) -> 196900 | P15: =SUM(L15:M15) -> 0 | Q15: =INT(SUMPRODUCT($L5:$M5,$L15:$M15)) -> 0
B16: （７）照査 | C16: 式 | D16: 1 | G16: 1.5 | N16: =SUM(E16:K16) -> 1.5 | O16: =INT(SUMPRODUCT($E$5:$K$5,$E16:$K16)) -> 100350 | P16: =SUM(L16:M16) -> 0 | Q16: =INT(SUMPRODUCT($L5:$M5,$L16:$M16)) -> 0
B17: （８）報告書作成 | C17: 式 | D17: 1 | H17: 1 | I17: 4 | J17: 1 | N17: =SUM(E17:K17) -> 6 | O17: =INT(SUMPRODUCT($E$5:$K$5,$E17:$K17)) -> 293900 | P17: =SUM(L17:M17) -> 0 | Q17: =INT(SUMPRODUCT($L5:$M5,$L17:$M17)) -> 0
N18: =SUM(E18:K18) -> 0 | O18: =INT(SUMPRODUCT($E$5:$K$5,$E18:$K18)) -> 0 | P18: =SUM(L18:M18) -> 0 | Q18: =INT(SUMPRODUCT($L5:$M5,$L18:$M18)) -> 0
N19: =SUM(E19:K19) -> 0 | O19: =INT(SUMPRODUCT($E$5:$K$5,$E19:$K19)) -> 0 | P19: =SUM(L19:M19) -> 0 | Q19: =INT(SUMPRODUCT($L5:$M5,$L19:$M19)) -> 0
N20: =SUM(E20:K20) -> 0 | O20: =INT(SUMPRODUCT($E$5:$K$5,$E20:$K20)) -> 0 | P20: =SUM(L20:M20) -> 0 | Q20: =INT(SUMPRODUCT($L5:$M5,$L20:$M20)) -> 0
N21: =SUM(E21:K21) -> 0 | O21: =INT(SUMPRODUCT($E$5:$K$5,$E21:$K21)) -> 0 | P21: =SUM(L21:M21) -> 0 | Q21: =INT(SUMPRODUCT($L5:$M5,$L21:$M21)) -> 0
N22: =SUM(E22:K22) -> 0 | O22: =INT(SUMPRODUCT($E$5:$K$5,$E22:$K22)) -> 0 | P22: =SUM(L22:M22) -> 0 | Q22: =INT(SUMPRODUCT($L5:$M5,$L22:$M22)) -> 0
N23: =SUM(E23:K23) -> 0 | O23: =INT(SUMPRODUCT($E$5:$K$5,$E23:$K23)) -> 0 | P23: =SUM(L23:M23) -> 0 | Q23: =INT(SUMPRODUCT($L5:$M5,$L23:$M23)) -> 0
N24: =SUM(E24:K24) -> 0 | O24: =INT(SUMPRODUCT($E$5:$K$5,$E24:$K24)) -> 0 | P24: =SUM(L24:M24) -> 0 | Q24: =INT(SUMPRODUCT($L5:$M5,$L24:$M24)) -> 0
N25: =SUM(E25:K25) -> 0 | O25: =INT(SUMPRODUCT($E$5:$K$5,$E25:$K25)) -> 0 | P25: =SUM(L25:M25) -> 0 | Q25: =INT(SUMPRODUCT($L5:$M5,$L25:$M25)) -> 0
N26: =SUM(E26:K26) -> 0 | O26: =INT(SUMPRODUCT($E$5:$K$5,$E26:$K26)) -> 0 | P26: =SUM(L26:M26) -> 0 | Q26: =INT(SUMPRODUCT($L5:$M5,$L26:$M26)) -> 0
N27: =SUM(E27:K27) -> 0 | O27: =INT(SUMPRODUCT($E$5:$K$5,$E27:$K27)) -> 0 | P27: =SUM(L27:M27) -> 0 | Q27: =INT(SUMPRODUCT($L5:$M5,$L27:$M27)) -> 0
N28: =SUM(E28:K28) -> 0 | O28: =INT(SUMPRODUCT($E$5:$K$5,$E28:$K28)) -> 0 | P28: =SUM(L28:M28) -> 0 | Q28: =INT(SUMPRODUCT($L5:$M5,$L28:$M28)) -> 0
B29: 合 計 | E29: =SUM(E6:E28) -> 0 | F29: =SUM(F6:F28) -> 0 | G29: =SUM(G6:G28) -> 3.5 | H29: =SUM(H6:H28) -> 10.5 | I29: =SUM(I6:I28) -> 15.5 | J29: =SUM(J6:J28) -> 9.5 | K29: =SUM(K6:K28) -> 28 | L29: =SUM(L6:L28) -> 0 | ... Q29: =SUM(Q6:Q28) -> 0
B30: 金額計 | E30: =INT(E5*E29) -> 0 | F30: =INT(F5*F29) -> 0 | G30: =INT(G5*G29) -> 234150 | H30: =INT(H5*H29) -> 625800 | I30: =INT(I5*I29) -> 751750 | J30: =INT(J5*J29) -> 382850 | K30: =INT(K5*K29) -> 1010800 | L30: =INT(L5*L29) -> 0 | M30: =INT(M5*M29) -> 0 | O30: =SUM(E30:K30) -> 3005350
R31: 八千代エンジニヤリング株式会社

Sheet 直接経費内訳
B3: =直接人件費!B2 -> 田原本停車場線 歩道設置検討業務委託（防災・安全（道環））
F4: 直 接 経 費 内 訳 書
B5: 名 称 | C5: 仕 様 | D5: 単位 | E5: 数 量 | F5: 単 価 | G5: 金 額 | H5: 摘 要
B26: 合 計 | G26: =SUM(G6:G25) -> 0
H27: 八千代エンジニヤリング株式会社

Sheet 単価
A1: 業種 | B1: 区分 | C1: 平成19年度 | D1: 平成20年度 | E1: 平成21年度 | F1: 平成22年度 | G1: 平成23年度 | H1: 平成24年度 | I1: 平成25年度 | J1: 平成26年度 | K1: 平成27年度 | L1: 平成28年度 | M1: 平成29年度 | N1: 平成30年度 | O1: 平成31年度 | P1: 令和2年度 | Q1: 令和3年度 | R1: 令和4年度 | S1: 令和5年度 | T1: 令和6年度 | U1: 令和7年度
B2: 主任技術者 | C2: 52800 | D2: 54100 | E2: 55800 | F2: 56900 | G2: 56600 | H2: 55000 | I2: 54700 | J2: 57000 | K2: 60100 | L2: 63700 | M2: 64300 | N2: 65500 | O2: 68800 | P2: 69800 | Q2: 69800 | R2: 70600 | S2: 74900 | T2: 80200 | U2: 88600
B3: 理事、技師長 | C3: 51400 | D3: 51600 | E3: 52400 | F3: 52100 | G3: 51800 | H3: 50900 | I3: 50800 | J3: 52900 | K3: 55800 | L3: 58400 | M3: 60400 | N3: 61700 | O3: 63500 | P3: 64800 | Q3: 65500 | R3: 66900 | S3: 70900 | T3: 75800 | U3: 77500
A4: 設 | B4: 主任技師 | C4: 45800 | D4: 45900 | E4: 47100 | F4: 45900 | G4: 45300 | H4: 44800 | I4: 44700 | J4: 47000 | K4: 49500 | L4: 49900 | M4: 51200 | N4: 52700 | O4: 53800 | P4: 55300 | Q4: 57400 | R4: 58600 | S4: 62200 | T4: 64800 | U4: 66900
B5: 技師(Ａ) | C5: 38300 | D5: 38300 | E5: 39300 | F5: 38900 | G5: 38900 | H5: 38500 | I5: 38900 | J5: 41000 | K5: 42800 | L5: 43500 | M5: 45500 | N5: 46300 | O5: 47500 | P5: 48700 | Q5: 51200 | R5: 51200 | S5: 55200 | T5: 57000 | U5: 59600
B6: 技師(Ｂ) | C6: 30300 | D6: 30500 | E6: 31300 | F6: 31300 | G6: 31600 | H6: 31300 | I6: 31500 | J6: 33400 | K6: 35100 | L6: 36600 | M6: 37200 | N6: 37900 | O6: 39100 | P6: 40600 | Q6: 40600 | R6: 41600 | S6: 45300 | T6: 47200 | U6: 48500
B7: 技師(Ｃ) | C7: 26000 | D7: 26000 | E7: 26200 | F7: 26500 | G7: 26200 | H7: 25700 | I7: 26200 | J7: 27100 | K7: 28400 | L7: 29900 | M7: 30000 | N7: 30800 | O7: 32000 | P7: 32700 | Q7: 32800 | R7: 32800 | S7: 35600 | T7: 38400 | U7: 40300
A8: 計 | B8: 技術員 | C8: 22100 | D8: 22100 | E8: 22400 | F8: 23000 | G8: 22700 | H8: 22200 | I8: 21800 | J8: 22600 | K8: 23800 | L8: 25100 | M8: 25400 | N8: 26200 | O8: 26400 | P8: 27900 | Q8: 29000 | R8: 29000 | S8: 31600 | T8: 33600 | U8: 36100
B9: 製図工 | D9: 18700 | E9: 19700 | F9: =F15 -> 20300 | G9: =G15 -> 20900 | H9: =H15 -> 21100 | I9: =I15 -> 20300 | J9: 21700 | K9: 23400 | L9: 25600 | M9: 26800 | N9: 28000 | O9: 29400
B10: キーパンチャー | D10: 15500 | E10: 15500 | F10: 15500 | G10: 15500 | H10: 15500 | I10: 15500
B11: 測量上級主任技師 | C11: 45100 | D11: 44600 | E11: 43300 | F11: 41900 | G11: 42300 | H11: 40900 | I11: 42000
A12: 測 | B12: 測量主任技師 | C12: 31900 | D12: 31100 | E12: 30300 | F12: 31200 | G12: 31100 | H12: 31000 | I12: 31600 | J12: 35200 | K12: 38100 | L12: 39000 | M12: 41400 | N12: 42200 | O12: 43500 | P12: 45400 | Q12: 45700 | R12: 48000 | S12: 51000 | T12: 54600 | U12: 60600
B13: 測量技師 | C13: 24900 | D13: 24700 | E13: 24700 | F13: 25500 | G13: 25800 | H13: 25700 | I13: 25700 | J13: 26900 | K13: 29200 | L13: 30500 | M13: 33300 | N13: 34800 | O13: 37600 | P13: 40000 | Q13: 40000 | R13: 42200 | S13: 44000 | T13: 47100 | U13: 52300
A14: 量 | B14: 測量技師補 | C14: 20400 | D14: 20400 | E14: 20900 | F14: 21700 | G14: 21500 | H14: 21600 | I14: 22400 | J14: 24600 | K14: 25500 | L14: 25700 | M14: 26900 | N14: 28100 | O14: 29500 | P14: 29700 | Q14: 30700 | R14: 32400 | S14: 34300 | T14: 36900 | U14: 41100
B15: 測量助手 | C15: 18500 | D15: 19300 | E15: 19700 | F15: 20300 | G15: 20900 | H15: 21100 | I15: 20300 | J15: 21700 | K15: 23400 | L15: 25600 | M15: 26800 | N15: 28000 | O15: 29400 | P15: 29500 | Q15: 29600 | R15: 31100 | S15: 32200 | T15: 34600 | U15: 34900
B16: 測量補助員 | K16: 20300 | L16: 21500 | M16: 21800 | N16: 22700 | O16: 23100 | P16: 23400 | Q16: 24200 | R16: 25400 | S16: 27000 | T16: 25900 | U16: 28700
B17: 操縦士 | C17: 40500 | D17: 42200 | E17: 44100 | F17: 44300 | G17: 44100 | H17: 43500 | I17: 43700 | J17: 43700 | K17: 43700 | L17: 43700 | M17: 45900 | N17: 47000 | O17: 50800 | P17: 53400 | Q17: 53400 | R17: 55300 | S17: 53600 | T17: 56300 | U17: 56300
A18: 撮 | B18: 整備士 | C18: 30400 | D18: 30600 | E18: 32100 | F18: 34100 | G18: 34400 | H18: 34500 | I18: 34100 | J18: 34200 | K18: 34600 | L18: 36000 | M18: 36000 | N18: 36700 | O18: 37800 | P18: 40000 | Q18: 40700 | R18: 42200 | S18: 40400 | T18: 43200 | U18: 43200
A19: 影 | B19: 撮影士 | C19: 31000 | D19: 30400 | E19: 30600 | F19: 31100 | G19: 30400 | H19: 30100 | I19: 30500 | J19: 30800 | K19: 31500 | L19: 32900 | M19: 34100 | N19: 35100 | O19: 35400 | P19: 36300 | Q19: 37300 | R19: 39300 | S19: 41600 | T19: 43500 | U19: 48200
B20: 撮影助手 | C20: 26400 | D20: 25500 | E20: 26000 | F20: 26000 | G20: 26800 | H20: 26000 | I20: 25900 | J20: 26600 | K20: 27400 | L20: 28000 | M20: 30000 | N20: 31100 | O20: 31100 | P20: 31700 | Q20: 31800 | R20: 31800 | S20: 33800 | T20: 36100 | U20: 36400
B21: 測量船操縦士 | K21: 23200 | L21: 24200 | M21: 24900 | N21: 26300 | O21: 27700 | P21: 29000 | Q21: 29700 | R21: 31400 | S21: 33500 | T21: 36300 | U21: 38300
A22: 地 | B22: 地質調査技師 | C22: 32900 | D22: 34400 | E22: 34800 | F22: 34600 | G22: 34200 | H22: 33400 | I22: 33700 | J22: 35600 | K22: 37400 | L22: 39900 | M22: 40900 | N22: 42900 | O22: 45400 | P22: 47400 | Q22: 47500 | R22: 50100 | S22: 53800 | T22: 53200 | U22: 56000
B23: 主任地質調査員 | C23: 28300 | D23: 28800 | E23: 27800 | F23: 27200 | G23: 27400 | H23: 27100 | I23: 27500 | J23: 29900 | K23: 31300 | L23: 32100 | M23: 32400 | N23: 33800 | O23: 34200 | P23: 35000 | Q23: 35000 | R23: 36800 | S23: 39100 | T23: 41500 | U23: 43800
A24: 質 | B24: 地質調査員 | C24: 20800 | D24: 22200 | E24: 22000 | F24: 21500 | G24: 21700 | H24: 21300 | I24: 20900 | J24: 22400 | K24: 22400 | L24: 23200 | M24: 23200 | N24: 23500 | O24: 24500 | P24: 24600 | Q24: 25900 | R24: 27200 | S24: 29100 | T24: 31400 | U24: 34100
B25: 普通作業員 | C25: 13000 | D25: 13300 | E25: 13300 | F25: 13300 | G25: 13300 | H25: 12900 | I25: 14700 | J25: =HLOOKUP(J$36,$C$265:$I$280,2,0) -> 15800 | K25: =HLOOKUP(K$36,$C$247:$N$262,2,0) -> 16400 | L25: =HLOOKUP(L$36,$C$229:$N$244,2,0) -> 17800 | M25: =HLOOKUP(M$36,$C$211:$N$226,2,0) -> 17700 | N25: =HLOOKUP(N$36,$C$190:$N$208,2,0) -> 18000 | O25: =HLOOKUP(O$36,$C$169:$N$187,2,0) -> 18700 | P25: =HLOOKUP(P$36,$C$148:$N$166,2,0) -> 19000 | Q25: =HLOOKUP(Q$36,$C$127:$N$145,2,0) -> 19000 | R25: =HLOOKUP(R$36,$C$106:$N$124,2,0) -> 19600 | S25: =HLOOKUP(S$36,$C$85:$N$103,2,0) -> 21000 | T25: =HLOOKUP(T$36,$C$64:$N$82,2,0) -> 21800 | U25: =HLOOKUP(U$36,$C$43:$N$61,2,0) -> 23300
A26: 労 | B26: 軽作業員 | D26: 10200 | E26: 10200 | F26: 10200 | G26: 10200 | H26: 10400 | I26: 11500 | J26: =HLOOKUP(J$36,$C$265:$I$280,3,0) -> 11900 | K26: =HLOOKUP(K$36,$C$247:$N$262,3,0) -> 11800 | L26: =HLOOKUP(L$36,$C$229:$N$244,3,0) -> 12300 | M26: =HLOOKUP(M$36,$C$211:$N$226,3,0) -> 12300 | N26: =HLOOKUP(N$36,$C$190:$N$208,3,0) -> 12500 | O26: =HLOOKUP(O$36,$C$169:$N$187,3,0) -> 13000 | P26: =HLOOKUP(P$36,$C$148:$N$166,3,0) -> 13200 | Q26: =HLOOKUP(Q$36,$C$127:$N$145,3,0) -> 13200 | R26: =HLOOKUP(R$36,$C$106:$N$124,3,0) -> 13200 | S26: =HLOOKUP(S$36,$C$85:$N$103,3,0) -> 14100 | T26: =HLOOKUP(T$36,$C$64:$N$82,3,0) -> 15200 | U26: =HLOOKUP(U$36,$C$43:$N$61,3,0) -> 16300
B27: 潜水士 | C27: 24800 | D27: 25000 | E27: 25000 | F27: 25000 | G27: 25000 | H27: 23300 | I27: 26700 | J27: =HLOOKUP(J$36,$C$265:$I$280,4,0) -> 29000 | K27: =HLOOKUP(K$36,$C$247:$N$262,4,0) -> 29900 | L27: =HLOOKUP(L$36,$C$229:$N$244,4,0) -> 30900 | M27: =HLOOKUP(M$36,$C$211:$N$226,4,0) -> 31600 | N27: =HLOOKUP(N$36,$C$190:$N$208,4,0) -> 31800 | O27: =HLOOKUP(O$36,$C$169:$N$187,4,0) -> 32700 | P27: =HLOOKUP(P$36,$C$148:$N$166,4,0) -> 33500 | Q27: =HLOOKUP(Q$36,$C$127:$N$145,4,0) -> 33500 | R27: =HLOOKUP(R$36,$C$106:$N$124,4,0) -> 35000 | S27: =HLOOKUP(S$36,$C$85:$N$103,4,0) -> 36300 | T27: =HLOOKUP(T$36,$C$64:$N$82,4,0) -> 38200 | U27: =HLOOKUP(U$36,$C$43:$N$61,4,0) -> 40200
B28: 潜水連絡員 | C28: 14300 | D28: 18600 | E28: 18600 | F28: 18600 | G28: 18600 | H28: 17300 | I28: 19800 | J28: =HLOOKUP(J$36,$C$265:$I$280,5,0) -> 21000 | K28: =HLOOKUP(K$36,$C$247:$N$262,5,0) -> 0 | L28: =HLOOKUP(L$36,$C$229:$N$244,5,0) -> 0 | M28: =HLOOKUP(M$36,$C$211:$N$226,5,0) -> 23400 | N28: =HLOOKUP(N$36,$C$190:$N$208,5,0) -> 23500 | O28: =HLOOKUP(O$36,$C$169:$N$187,5,0) -> 24100 | P28: =HLOOKUP(P$36,$C$148:$N$166,5,0) -> 24700 | Q28: =HLOOKUP(Q$36,$C$127:$N$145,5,0) -> 24700 | R28: =HLOOKUP(R$36,$C$106:$N$124,5,0) -> 26000 | S28: =HLOOKUP(S$36,$C$85:$N$103,5,0) -> 0
A29: 務 | B29: 潜水送気員 | C29: 17400 | D29: 18500 | E29: 18500 | F29: 18500 | G29: 18500 | H29: 17300 | I29: 19200 | J29: =HLOOKUP(J$36,$C$265:$I$280,6,0) -> 20400 | K29: =HLOOKUP(K$36,$C$247:$N$262,6,0) -> 21100 | L29: =HLOOKUP(L$36,$C$229:$N$244,6,0) -> 21900 | M29: =HLOOKUP(M$36,$C$211:$N$226,6,0) -> 22400 | N29: =HLOOKUP(N$36,$C$190:$N$208,6,0) -> 22500 | O29: =HLOOKUP(O$36,$C$169:$N$187,6,0) -> 23100 | P29: =HLOOKUP(P$36,$C$148:$N$166,6,0) -> 23700 | Q29: =HLOOKUP(Q$36,$C$127:$N$145,6,0) -> 23700 | R29: =HLOOKUP(R$36,$C$106:$N$124,6,0) -> 24800 | S29: =HLOOKUP(S$36,$C$85:$N$103,6,0) -> 27000 | T29: =HLOOKUP(T$36,$C$64:$N$82,6,0) -> 29700 | U29: =HLOOKUP(U$36,$C$43:$N$61,6,0) -> 31300
B30: 潜水世話役 | C30: 27700 | D30: 27700 | E30: 27700 | F30: 27700 | G30: 27700 | H30: 27700 | I30: 27700 | J30: =HLOOKUP(J$36,$C$265:$I$280,7,0) -> 0 | K30: =HLOOKUP(K$36,$C$247:$N$262,7,0) -> 0 | L30: =HLOOKUP(L$36,$C$229:$N$244,7,0) -> 0 | M30: =HLOOKUP(M$36,$C$211:$N$226,7,0) -> 0 | N30: =HLOOKUP(N$36,$C$190:$N$208,7,0) -> 0 | O30: =HLOOKUP(O$36,$C$169:$N$187,7,0) -> 0 | P30: =HLOOKUP(P$36,$C$148:$N$166,7,0) -> 0 | Q30: =HLOOKUP(Q$36,$C$127:$N$145,7,0) -> 0 | R30: =HLOOKUP(R$36,$C$106:$N$124,7,0) -> 0 | S30: =HLOOKUP(S$36,$C$85:$N$103,7,0) -> 0
B31: 点検整備工 | C31: 29800 | D31: 29800 | E31: 29800 | F31: 29800 | G31: 29800 | H31: 29800 | I31: 29800 | J31: =HLOOKUP(J$36,$C$265:$I$280,8,0) -> 0 | K31: =HLOOKUP(K$36,$C$247:$N$262,8,0) -> 0 | L31: =HLOOKUP(L$36,$C$229:$N$244,8,0) -> 0 | M31: =HLOOKUP(M$36,$C$211:$N$226,8,0) -> 0 | N31: =HLOOKUP(N$36,$C$190:$N$208,8,0) -> 0 | O31: =HLOOKUP(O$36,$C$169:$N$187,8,0) -> 0 | P31: =HLOOKUP(P$36,$C$148:$N$166,8,0) -> 0 | Q31: =HLOOKUP(Q$36,$C$127:$N$145,8,0) -> 0 | R31: =HLOOKUP(R$36,$C$106:$N$124,8,0) -> 0 | S31: =HLOOKUP(S$36,$C$85:$N$103,8,0) -> 0
A32: 費 | B32: 交通誘導員A | D32: 8000 | E32: 8000 | F32: 8000 | G32: 8000 | H32: 8400 | I32: 9500 | J32: =HLOOKUP(J$36,$C$265:$I$280,9,0) -> 10500 | K32: =HLOOKUP(K$36,$C$247:$N$262,9,0) -> 10900 | L32: =HLOOKUP(L$36,$C$229:$N$244,9,0) -> 11400 | M32: =HLOOKUP(M$36,$C$211:$N$226,9,0) -> 11700 | N32: =HLOOKUP(N$36,$C$190:$N$208,9,0) -> 12200 | O32: =HLOOKUP(O$36,$C$169:$N$187,9,0) -> 12800 | P32: =HLOOKUP(P$36,$C$148:$N$166,9,0) -> 13200 | Q32: =HLOOKUP(Q$36,$C$127:$N$145,9,0) -> 13700 | R32: =HLOOKUP(R$36,$C$106:$N$124,9,0) -> 13700 | S32: =HLOOKUP(S$36,$C$85:$N$103,9,0) -> 15000 | T32: =HLOOKUP(T$36,$C$64:$N$82,9,0) -> 16200 | U32: =HLOOKUP(U$36,$C$43:$N$61,9,0) -> 17400
B33: 交通誘導員B | D33: 7500 | E33: 7500 | F33: 7500 | G33: 7500 | H33: 7500 | I33: 8500 | J33: =HLOOKUP(J$36,$C$265:$I$280,10,0) -> 9100 | K33: =HLOOKUP(K$36,$C$247:$N$262,10,0) -> 9200 | L33: =HLOOKUP(L$36,$C$229:$N$244,10,0) -> 10000 | M33: =HLOOKUP(M$36,$C$211:$N$226,10,0) -> 10200 | N33: =HLOOKUP(N$36,$C$190:$N$208,10,0) -> 10600 | O33: =HLOOKUP(O$36,$C$169:$N$187,10,0) -> 11100 | P33: =HLOOKUP(P$36,$C$148:$N$166,10,0) -> 11500 | Q33: =HLOOKUP(Q$36,$C$127:$N$145,10,0) -> 11700 | R33: =HLOOKUP(R$36,$C$106:$N$124,10,0) -> 12100 | S33: =HLOOKUP(S$36,$C$85:$N$103,10,0) -> 12700 | T33: =HLOOKUP(T$36,$C$64:$N$82,10,0) -> 14000 | U33: =HLOOKUP(U$36,$C$43:$N$61,10,0) -> 15000
B34: 高級船員 | D34: 21100 | E34: 21100 | F34: 21100 | G34: 21100 | H34: 19900 | I34: 22700 | J34: =HLOOKUP(J$36,$C$265:$I$280,11,0) -> 23500 | K34: =HLOOKUP(K$36,$C$247:$N$262,11,0) -> 23400 | L34: =HLOOKUP(L$36,$C$229:$N$244,11,0) -> 24100 | M34: =HLOOKUP(M$36,$C$211:$N$226,11,0) -> 25100 | N34: =HLOOKUP(N$36,$C$190:$N$208,11,0) -> 25500 | O34: =HLOOKUP(O$36,$C$169:$N$187,11,0) -> 25800 | P34: =HLOOKUP(P$36,$C$148:$N$166,11,0) -> 26700 | Q34: =HLOOKUP(Q$36,$C$127:$N$145,11,0) -> 27900 | R34: =HLOOKUP(R$36,$C$106:$N$124,11,0) -> 27900 | S34: =HLOOKUP(S$36,$C$85:$N$103,11,0) -> 29200 | T34: =HLOOKUP(T$36,$C$64:$N$82,11,0) -> 31100 | U34: =HLOOKUP(U$36,$C$43:$N$61,11,0) -> 33400
B35: 普通船員 | D35: 17100 | E35: 17100 | F35: 17100 | G35: 17100 | H35: 16100 | I35: 17700 | J35: =HLOOKUP(J$36,$C$265:$I$280,12,0) -> 19100 | K35: =HLOOKUP(K$36,$C$247:$N$262,12,0) -> 19100 | L35: =HLOOKUP(L$36,$C$229:$N$244,12,0) -> 18800 | M35: =HLOOKUP(M$36,$C$211:$N$226,12,0) -> 19100 | N35: =HLOOKUP(N$36,$C$190:$N$208,12,0) -> 19400 | O35: =HLOOKUP(O$36,$C$169:$N$187,12,0) -> 19600 | P35: =HLOOKUP(P$36,$C$148:$N$166,12,0) -> 21300 | Q35: =HLOOKUP(Q$36,$C$127:$N$145,12,0) -> 21300 | R35: =HLOOKUP(R$36,$C$106:$N$124,12,0) -> 21700 | S35: =HLOOKUP(S$36,$C$85:$N$103,12,0) -> 22700 | T35: =HLOOKUP(T$36,$C$64:$N$82,12,0) -> 24800 | U35: =HLOOKUP(U$36,$C$43:$N$61,12,0) -> 26500
J36: 大阪府 | K36: 大阪府 | L36: 大阪府 | M36: 大阪府 | N36: 大阪府 | O36: 大阪府 | P36: 大阪府 | Q36: 大阪府 | R36: 大阪府 | S36: 大阪府 | T36: 大阪府 | U36: 大阪府
B37: 注：使用注意 | J37: ↑
J38: 適用する府県名を選択してください
A42: R7府県別設計労務単価
C43: 福井県 | D43: 滋賀県 | E43: 京都府 | F43: 大阪府 | G43: 兵庫県 | H43: 奈良県 | I43: 和歌山県 | J43: 徳島県 | K43: 香川県 | L43: 愛媛県 | M43: 高知県
...
